Workbook
Name Slicer_Branch_code: #N/A
Name Slicer_Delivery_Status: #N/A

Sheet Raw_Data
A1: Order_ID | B1: Order_Date | C1: Order_Time | D1: Branch_code | E1: Cuisine | F1: Item_Name | G1: Customer_Name | H1: Order_Value | I1: Delivery_Time_Min | J1: Rating | K1: Payment_Mode
A2: ORD1001 | B2: 46027 | C2: 0.35416667 | D2: BLR01 | E2: South Indian | F2: Masala Dosa | G2: Nithya | H2: 80 | I2: 30 | J2: 4 | K2: UPI
A3: ORD1002 | B3: 46027 | C3: 0.40625 | D3: KL02 | E3: Fast Food | F3: Chicken Burger | G3: Seetha | H3: 127 | I3: 23 | J3: 2 | K3: Cash
A4: ORD1003 | B4: 46056 | C4: 0.41875 | D4: HYD10 | E4: North Indian | F4: Butter Chicken | G4: Geetha | H4: 229 | I4: 15 | J4: 3 | K4: Credit/Debit Card
A5: ORD1004 | B5: 46057 | C5: 0.45833333 | D5: AP02 | E5: Chinese | F5: Manchurian Rice | G5: Ramya | H5: 175 | I5: 12 | J5: 1 | K5: UPI
A6: ORD1005 | B6: 46058 | C6: 0.51388889 | D6: TN12 | E6: Deserts/Bakery | F6: Gulab Jamun | G6: Teja | H6: 274 | I6: 40 | J6: 5 | K6: Cash
A7: ORD1006 | B7: 46059 | C7: 0.35416667 | D7: BLR01 | E7: South Indian | F7: Masala Dosa | G7: Asmitha | H7: 231 | I7: 25 | J7: 3 | K7: Credit/Debit Card
A8: ORD1007 | B8: 46060 | C8: 0.55555556 | D8: BLR01 | E8: Fast Food | F8: Frenchfries | G8: Ashrith | H8: 160 | I8: 32 | J8: 4 | K8: Cash
A9: ORD1008 | B9: 46061 | C9: 0.47222222 | D9: KL02 | E9: North Indian | F9: Dalmakhani | G9: Ajay | H9: 239 | I9: 30 | J9: 2 | K9: Credit/Debit Card
A10: ORD1009 | B10: 46063 | C10: 0.60416667 | D10: HYD10 | E10: Chinese | F10: Hakkanoodles | G10: Sai | H10: 280 | I10: 12 | J10: 5 | K10: UPI
A11: ORD1010 | B11: 11/02/2026 | C11: 0.52083333 | D11: AP02 | E11: Deserts/Bakery | F11: Gulabjamun | G11: Bharath | H11: 163 | I11: 10 | J11: 1 | K11: Cash
A12: ORD1011 | B12: 46065 | C12: 0.47916667 | D12: TN12 | E12: South Indian | F12: Idli Sambar | G12: Asmitha | H12: 208 | I12: 10 | J12: 4 | K12: UPI
A13: ORD1012 | B13: 12/02-2026 | C13: 0.52777778 | D13: BLR01 | E13: Fast Food | F13: chickenburger | G13: Sheela | H13: 272 | I13: 20 | J13: 2 | K13: Cash
A14: ORD1013 | B14: 12/02/2026 | C14: 0.5625 | D14: BLR01 | E14: North Indian | F14: butterchicken | G14: Joshna | H14: 242 | I14: 20 | J14: 4 | K14: Credit/Debit Card
A15: ORD1014 | B15: 12/02/2026 | C15: 0.6875 | D15: KL02 | E15: Chinese | F15: Masala Dosa | G15: Indhu | H15: 123 | I15: 20 | J15: 3 | K15: UPI
A16: ORD1015 | B16: 46066 | C16: 0.38888889 | D16: HYD10 | E16: Deserts/Bakery | F16: Chicken Burger | G16: Dhanush | H16: 192 | I16: 30 | J16: 2 | K16: Cash
A17: ORD1016 | B17: 46067 | C17: 0.43055556 | D17: AP02 | E17: Chinese | F17: Butter Chicken | G17: Dheeraj | H17: 143 | I17: 20 | J17: 4 | K17: Credit/Debit Card
A18: ORD1017 | B18: 46068 | C18: 0.56944444 | D18: TN12 | E18: Deserts/Bakery | F18: Manchurian Rice | G18: Vaishnavi | H18: 277 | I18: 34 | J18: 1 | K18: Cash
A19: ORD1018 | B19: 46069 | C19: 0.52083333 | D19: BLR01 | E19: South Indian | F19: Gulab Jamun | G19: Jay | H19: 212 | I19: 36 | J19: 4 | K19: Cash
A20: ORD1019 | B20: 46070 | C20: 0.60416667 | D20: BLR01 | E20: Fast Food | F20: Masala Dosa | G20: Kiran | H20: 165 | I20: 26 | J20: 5 | K20: UPI
A21: ORD1020 | B21: 46071 | C21: 0.47916667 | D21: KL02 | E21: North Indian | F21: Frenchfries | G21: Varsha | H21: 153 | I21: 18 | J21: 4 | K21: Cash
A22: ORD1021 | B22: 46072 | C22: 0.53125 | D22: HYD10 | E22: Chinese | F22: Dalmakhani | G22: Varshith | H22: 127 | I22: 229 | J22: 2 | K22: Credit/Debit Card
A23: ORD1022 | B23: 46073 | C23: 0.35416667 | D23: AP02 | E23: Deserts/Bakery | F23: Hakkanoodles | G23: Varun | H23: 187 | I23: 31 | J23: 3 | K23: Cash
A24: ORD1023 | B24: 46074 | C24: 0.40625 | D24: TN12 | E24: North Indian | F24: Gulabjamun | G24: Tejas | H24: 150 | I24: 36 | J24: 2 | K24: UPI
A25: ORD1024 | B25: 22/02/2026 | C25: 0.4375 | D25: BLR01 | E25: Chinese | F25: Idli Sambar | G25: Tharuni | H25: 266 | I25: 39 | J25: 3 | K25: UPI
A26: ORD1025 | B26: 23/02/2026 | C26: 0.52083333 | D26: BLR01 | E26: Deserts/Bakery | F26: chickenburger | G26: Bindhu | H26: 127 | I26: 42 | J26: 4 | K26: Cash
A27: ORD1026 | B27: 46077 | C27: 0.47916667 | D27: KL02 | E27: Chinese | F27: butterchicken | G27: Madhavi | H27: 235 | I27: 14 | J27: 3 | K27: Credit/Debit Card
A28: ORD1027 | B28: 46078 | C28: 0.52777778 | D28: HYD10 | E28: Deserts/Bakery | F28: Gulabjamun | G28: Navadeep | H28: 242 | I28: 16 | J28: 4 | K28: Cash
A29: ORD1028 | B29: 46079 | C29: 0.5625 | D29: AP02 | E29: South Indian | F29: Idli Sambar | G29: Abhi | H29: 199 | I29: 27 | J29: 4 | K29: UPI
A30: ORD1029 | B30: 27/02/2026 | C30: 0.6875 | D30: TN12 | E30: Fast Food | F30: chickenburger | G30: Tharun | H30: 282 | I30: 18 | J30: 2 | K30: Cash
A31: ORD1030 | B31: 46081 | C31: 0.38888889 | D31: BLR01 | E31: North Indian | F31: butterchicken | G31: Vedha | H31: 284 | I31: 26 | J31: 4 | K31: Credit/Debit Card
A32: ORD1031 | B32: 46082 | C32: 0.43055556 | D32: BLR01 | E32: Chinese | F32: Masala Dosa | G32: Vennela | H32: 137 | I32: 19 | J32: 4 | K32: Cash
A33: ORD1032 | B33: 46083 | C33: 0.56944444 | D33: KL02 | E33: Deserts/Bakery | F33: Chicken Burger | G33: Harshini | H33: 139 | I33: 18 | J33: 3 | K33: Credit/Debit Card
A34: ORD1033 | B34: 3 March 2026 | C34: 0.52083333 | D34: HYD10 | E34: South Indian | F34: Butter Chicken | G34: Ali | H34: 164 | I34: 27 | J34: 5 | K34: UPI
A35: ORD1034 | B35: 46085 | C35: 0.60416667 | D35: AP02 | E35: Fast Food | F35: Manchurian Rice | G35: dheeraj | H35: 205 | I35: 37 | J35: 3 | K35: UPI
A36: ORD1035 | B36: 3 MArch-2026 | C36: 0.47916667 | D36: TN12 | E36: North Indian | F36: Gulab Jamun | G36: Ravi | H36: 293 | I36: 18 | J36: 3 | K36: Cash
A37: ORD1036 | B37: 46087 | C37: 0.53125 | D37: BLR01 | E37: Chinese | F37: Masala Dosa | G37: sai | H37: 106 | I37: 26 | J37: 3 | K37: Cash
A38: ORD1037 | B38: 46088 | C38: 0.35416667 | D38: BLR01 | E38: Deserts/Bakery | F38: Chicken Burger | G38: Bharath | H38: 171 | I38: 28 | J38: 2 | K38: UPI
A39: ORD1038 | B39: 46089 | C39: 0.40625 | D39: KL02 | E39: South Indian | F39: Butter Chicken | G39: Joshna | H39: 253 | I39: 16 | J39: 4 | K39: UPI
A40: ORD1039 | B40: 46090 | C40: 0.4375 | D40: HYD10 | E40: Fast Food | F40: Manchurian Rice | G40: vedha | H40: 164 | I40: 18 | J40: 2 | K40: Cash
...

Sheet Master_Branch
A1: Branch_Code | B1: Branch_Name | C1: City | D1: Manager
A2: BLR01 | B2: Koramangala | C2: Bengaluru | D2: Anitha
A3: KL02 | B3: MG Road | C3: Kochi | D3: Vikram
A4: HYD10 | B4: LB Nagar | C4: Hyderabad | D4: Vijay
A5: AP02 | B5: Vijayawada Central | C5: Vijaywada | D5: Rohit
A6: TN12 | B6: T Nagar | C6: Chennai | D6: Harsha

Sheet Master_Menu Item
A1: Item_Name | B1: Cuisine | C1: Price | D1: Category
A2: Butter Chicken | B2: North Indian | C2: 320 | D2: Main Course
A3: Hakka Noodles | B3: Chinese | C3: 220 | D3: Main Course
A4: Gulab Jamun | B4: Deserts/Bakery | C4: 120 | D4: Desert
A5: Masala Dosa | B5: South Indian | C5: 150 | D5: Breakfast
A6: Idli Sambar | B6: South Indian | C6: 130 | D6: Breakfast
A7: Manchurian Rice | B7: Chinese | C7: 210 | D7: Main Course
A8: Chicken Burger | B8: Fast Food | C8: 180 | D8: Fast Food
A9: French fries | B9: Fast Food | C9: 140 | D9: Fast Food
A10: Dal Makhani | B10: North Indian | C10: 260 | D10: Main Course

Sheet Clean_Data
A1: Order_ID | B1: Order_Date | C1: Order_Time | D1: Branch_code | E1: Cuisine | F1: Item_Name | G1: Customer_Name | H1: Order_Value | I1: Delivery_Time_Min | J1: Rating | K1: Payment_Mode | L1: Correct_Cuisine | M1: Clean_Customer_Name | N1: City | O1: Order_Day | P1: Order_Month | Q1: Delivery_Status | R1: Rating_Category
A2: ORD1001 | B2: 46027 | C2: 0.35416667 | D2: BLR01 | E2: South Indian | F2: Masala Dosa | G2: Nithya | H2: 80 | I2: 30 | J2: 4 | K2: UPI | L2: =INDEX('Master_Menu Item'!$B:$B, MATCH(F2,'Master_Menu Item'!$A:$A,0)) -> South Indian | M2: =PROPER(TRIM(G2)) -> Nithya | N2: =INDEX(Master_Branch!$C:$C, MATCH(D2,Master_Branch!$A:$A,0)) -> Bengaluru | O2: =TEXT(B2,"dddd") -> Monday | P2: =DATE(YEAR(B2),MONTH(B2),1) -> 46023 | Q2: =_xlfn.IFS(I2<=20,"Fast", I2<=35,"Normal", I2>35,"Slow") -> Normal | R2: =IF(J2>=4,"Good","Needs Improvement") -> Good
A3: ORD1002 | B3: 46027 | C3: 0.40625 | D3: KL02 | E3: Fast Food | F3: Chicken Burger | G3: Seetha | H3: 127 | I3: 23 | J3: 2 | K3: Cash | L3: =INDEX('Master_Menu Item'!$B:$B, MATCH(F3,'Master_Menu Item'!$A:$A,0)) -> Fast Food | M3: =PROPER(TRIM(G3)) -> Seetha | N3: =INDEX(Master_Branch!$C:$C, MATCH(D3,Master_Branch!$A:$A,0)) -> Kochi | O3: =TEXT(B3,"dddd") -> Monday | P3: =DATE(YEAR(B3),MONTH(B3),1) -> 46023 | Q3: =_xlfn.IFS(I3<=20,"Fast", I3<=35,"Normal", I3>35,"Slow") -> Normal | R3: =IF(J3>=4,"Good","Needs Improvement") -> Needs Improvement
A4: ORD1003 | B4: 46056 | C4: 0.41875 | D4: HYD10 | E4: North Indian | F4: Butter Chicken | G4: Geetha | H4: 229 | I4: 15 | J4: 3 | K4: Credit/Debit Card | L4: =INDEX('Master_Menu Item'!$B:$B, MATCH(F4,'Master_Menu Item'!$A:$A,0)) -> North Indian | M4: =PROPER(TRIM(G4)) -> Geetha | N4: =INDEX(Master_Branch!$C:$C, MATCH(D4,Master_Branch!$A:$A,0)) -> Hyderabad | O4: =TEXT(B4,"dddd") -> Tuesday | P4: =DATE(YEAR(B4),MONTH(B4),1) -> 46054 | Q4: =_xlfn.IFS(I4<=20,"Fast", I4<=35,"Normal", I4>35,"Slow") -> Fast | R4: =IF(J4>=4,"Good","Needs Improvement") -> Needs Improvement
A5: ORD1004 | B5: 46057 | C5: 0.45833333 | D5: AP02 | E5: Chinese | F5: Manchurian Rice | G5: Ramya | H5: 175 | I5: 12 | J5: 1 | K5: UPI | L5: =INDEX('Master_Menu Item'!$B:$B, MATCH(F5,'Master_Menu Item'!$A:$A,0)) -> Chinese | M5: =PROPER(TRIM(G5)) -> Ramya | N5: =INDEX(Master_Branch!$C:$C, MATCH(D5,Master_Branch!$A:$A,0)) -> Vijaywada | O5: =TEXT(B5,"dddd") -> Wednesday | P5: =DATE(YEAR(B5),MONTH(B5),1) -> 46054 | Q5: =_xlfn.IFS(I5<=20,"Fast", I5<=35,"Normal", I5>35,"Slow") -> Fast | R5: =IF(J5>=4,"Good","Needs Improvement") -> Needs Improvement
A6: ORD1005 | B6: 46058 | C6: 0.51388889 | D6: TN12 | E6: Deserts/Bakery | F6: Gulab Jamun | G6: Teja | H6: 274 | I6: 40 | J6: 5 | K6: Cash | L6: =INDEX('Master_Menu Item'!$B:$B, MATCH(F6,'Master_Menu Item'!$A:$A,0)) -> Deserts/Bakery | M6: =PROPER(TRIM(G6)) -> Teja | N6: =INDEX(Master_Branch!$C:$C, MATCH(D6,Master_Branch!$A:$A,0)) -> Chennai | O6: =TEXT(B6,"dddd") -> Thursday | P6: =DATE(YEAR(B6),MONTH(B6),1) -> 46054 | Q6: =_xlfn.IFS(I6<=20,"Fast", I6<=35,"Normal", I6>35,"Slow") -> Slow | R6: =IF(J6>=4,"Good","Needs Improvement") -> Good
A7: ORD1006 | B7: 46059 | C7: 0.35416667 | D7: BLR01 | E7: South Indian | F7: Masala Dosa | G7: Asmitha | H7: 231 | I7: 25 | J7: 3 | K7: Credit/Debit Card | L7: =INDEX('Master_Menu Item'!$B:$B, MATCH(F7,'Master_Menu Item'!$A:$A,0)) -> South Indian | M7: =PROPER(TRIM(G7)) -> Asmitha | N7: =INDEX(Master_Branch!$C:$C, MATCH(D7,Master_Branch!$A:$A,0)) -> Bengaluru | O7: =TEXT(B7,"dddd") -> Friday | P7: =DATE(YEAR(B7),MONTH(B7),1) -> 46054 | Q7: =_xlfn.IFS(I7<=20,"Fast", I7<=35,"Normal", I7>35,"Slow") -> Normal | R7: =IF(J7>=4,"Good","Needs Improvement") -> Needs Improvement
A8: ORD1007 | B8: 46060 | C8: 0.55555556 | D8: BLR01 | E8: Fast Food | F8: French Fries | G8: Ashrith | H8: 160 | I8: 32 | J8: 4 | K8: Cash | L8: =INDEX('Master_Menu Item'!$B:$B, MATCH(F8,'Master_Menu Item'!$A:$A,0)) -> Fast Food | M8: =PROPER(TRIM(G8)) -> Ashrith | N8: =INDEX(Master_Branch!$C:$C, MATCH(D8,Master_Branch!$A:$A,0)) -> Bengaluru | O8: =TEXT(B8,"dddd") -> Saturday | P8: =DATE(YEAR(B8),MONTH(B8),1) -> 46054 | Q8: =_xlfn.IFS(I8<=20,"Fast", I8<=35,"Normal", I8>35,"Slow") -> Normal | R8: =IF(J8>=4,"Good","Needs Improvement") -> Good
A9: ORD1008 | B9: 46061 | C9: 0.47222222 | D9: KL02 | E9: North Indian | F9: Dal Makhani | G9: Ajay | H9: 239 | I9: 30 | J9: 2 | K9: Credit/Debit Card | L9: =INDEX('Master_Menu Item'!$B:$B, MATCH(F9,'Master_Menu Item'!$A:$A,0)) -> North Indian | M9: =PROPER(TRIM(G9)) -> Ajay | N9: =INDEX(Master_Branch!$C:$C, MATCH(D9,Master_Branch!$A:$A,0)) -> Kochi | O9: =TEXT(B9,"dddd") -> Sunday | P9: =DATE(YEAR(B9),MONTH(B9),1) -> 46054 | Q9: =_xlfn.IFS(I9<=20,"Fast", I9<=35,"Normal", I9>35,"Slow") -> Normal | R9: =IF(J9>=4,"Good","Needs Improvement") -> Needs Improvement
A10: ORD1009 | B10: 46063 | C10: 0.60416667 | D10: HYD10 | E10: Chinese | F10: Hakka Noodles | G10: Sai | H10: 280 | I10: 12 | J10: 5 | K10: UPI | L10: =INDEX('Master_Menu Item'!$B:$B, MATCH(F10,'Master_Menu Item'!$A:$A,0)) -> Chinese | M10: =PROPER(TRIM(G10)) -> Sai | N10: =INDEX(Master_Branch!$C:$C, MATCH(D10,Master_Branch!$A:$A,0)) -> Hyderabad | O10: =TEXT(B10,"dddd") -> Tuesday | P10: =DATE(YEAR(B10),MONTH(B10),1) -> 46054 | Q10: =_xlfn.IFS(I10<=20,"Fast", I10<=35,"Normal", I10>35,"Slow") -> Fast | R10: =IF(J10>=4,"Good","Needs Improvement") -> Good
A11: ORD1010 | B11: 46064 | C11: 0.52083333 | D11: AP02 | E11: Deserts/Bakery | F11: Gulab Jamun | G11: Bharath | H11: 163 | I11: 10 | J11: 1 | K11: Cash | L11: =INDEX('Master_Menu Item'!$B:$B, MATCH(F11,'Master_Menu Item'!$A:$A,0)) -> Deserts/Bakery | M11: =PROPER(TRIM(G11)) -> Bharath | N11: =INDEX(Master_Branch!$C:$C, MATCH(D11,Master_Branch!$A:$A,0)) -> Vijaywada | O11: =TEXT(B11,"dddd") -> Wednesday | P11: =DATE(YEAR(B11),MONTH(B11),1) -> 46054 | Q11: =_xlfn.IFS(I11<=20,"Fast", I11<=35,"Normal", I11>35,"Slow") -> Fast | R11: =IF(J11>=4,"Good","Needs Improvement") -> Needs Improvement
A12: ORD1011 | B12: 46065 | C12: 0.47916667 | D12: TN12 | E12: South Indian | F12: Idli Sambar | G12: Asmitha | H12: 208 | I12: 10 | J12: 4 | K12: UPI | L12: =INDEX('Master_Menu Item'!$B:$B, MATCH(F12,'Master_Menu Item'!$A:$A,0)) -> South Indian | M12: =PROPER(TRIM(G12)) -> Asmitha | N12: =INDEX(Master_Branch!$C:$C, MATCH(D12,Master_Branch!$A:$A,0)) -> Chennai | O12: =TEXT(B12,"dddd") -> Thursday | P12: =DATE(YEAR(B12),MONTH(B12),1) -> 46054 | Q12: =_xlfn.IFS(I12<=20,"Fast", I12<=35,"Normal", I12>35,"Slow") -> Fast | R12: =IF(J12>=4,"Good","Needs Improvement") -> Good
A13: ORD1012 | B13: 46065 | C13: 0.52777778 | D13: BLR01 | E13: Fast Food | F13: Chicken Burger | G13: Sheela | H13: 272 | I13: 20 | J13: 2 | K13: Cash | L13: =INDEX('Master_Menu Item'!$B:$B, MATCH(F13,'Master_Menu Item'!$A:$A,0)) -> Fast Food | M13: =PROPER(TRIM(G13)) -> Sheela | N13: =INDEX(Master_Branch!$C:$C, MATCH(D13,Master_Branch!$A:$A,0)) -> Bengaluru | O13: =TEXT(B13,"dddd") -> Thursday | P13: =DATE(YEAR(B13),MONTH(B13),1) -> 46054 | Q13: =_xlfn.IFS(I13<=20,"Fast", I13<=35,"Normal", I13>35,"Slow") -> Fast | R13: =IF(J13>=4,"Good","Needs Improvement") -> Needs Improvement
... A161: ORD1160 | B161: 46211 | C161: 0.66944444 | D161: KL02 | E161: North Indian | F161: Idli Sambar | G161: Himathi | H161: 234 | I161: 12 | J161: 3 | K161: Credit/Debit Card | L161: =INDEX('Master_Menu Item'!$B:$B, MATCH(F161,'Master_Menu Item'!$A:$A,0)) -> South Indian | M161: =PROPER(TRIM(G161)) -> Himathi | N161: =INDEX(Master_Branch!$C:$C, MATCH(D161,Master_Branch!$A:$A,0)) -> Kochi | O161: =TEXT(B161,"dddd") -> Wednesday | P161: =DATE(YEAR(B161),MONTH(B161),1) -> 46204 | Q161: =_xlfn.IFS(I161<=20,"Fast", I161<=35,"Normal", I161>35,"Slow") -> Fast | R161: =IF(J161>=4,"Good","Needs Improvement") -> Needs Improvement

Sheet Summary
A1: Revenue by Branch
A2: BLR01 | B2: =SUMIFS(Clean_Data!$H:$H, Clean_Data!$D:$D, "BLR01") -> 10505 | E2: Revenue By Cuisine
A3: HYD10 | B3: =SUMIFS(Clean_Data!$H:$H, Clean_Data!$D:$D, "HYD10") -> 6203 | E3: South Indian | F3: =SUMIFS(Clean_Data!$H:$H, Clean_Data!$L:$L, "South Indian") -> 6231
A4: AP02 | B4: =SUMIFS(Clean_Data!$H:$H, Clean_Data!$D:$D, "AP02") -> 4143 | E4: North Indian | F4: =SUMIFS(Clean_Data!$H:$H, Clean_Data!$L:$L, "North Indian") -> 7462
A5: TN12 | B5: =SUMIFS(Clean_Data!$H:$H, Clean_Data!$D:$D, "TN12") -> 5201 | E5: Fast Food | F5: =SUMIFS(Clean_Data!$H:$H, Clean_Data!$L:$L, "Fast Food") -> 7333
A6: KL02 | B6: =SUMIFS(Clean_Data!$H:$H, Clean_Data!$D:$D, "KL02") -> 5453 | E6: Deserts/Bakery | F6: =SUMIFS(Clean_Data!$H:$H, Clean_Data!$L:$L, "Deserts/Bakery") -> 5654
A7: SUM | B7: =SUM(B2:B6) -> 31505 | E7: Chinese | F7: =SUMIFS(Clean_Data!$H:$H, Clean_Data!$L:$L, "Chinese") -> 4825
E8: SUM | F8: =SUM(F3:F7) -> 31505
A10: Average Delivery Time by Branch
A11: BLR01 | B11: =AVERAGEIFS(Clean_Data!$I:$I, Clean_Data!$D:$D, "BLR01") -> 26.226415 | E11: Orders by Rating_Category
A12: HYD10 | B12: =AVERAGEIFS(Clean_Data!$I:$I, Clean_Data!$D:$D, "HYD10") -> 29.848485 | E12: Good | F12: =COUNTIF(Clean_Data!$R:$R, "Good") -> 68
A13: AP02 | B13: =AVERAGEIFS(Clean_Data!$I:$I, Clean_Data!$D:$D, "AP02") -> 22.285714 | E13: Needs Improvement | F13: =COUNTIF(Clean_Data!$R:$R, "Needs Improvement") -> 92
A14: TN12 | B14: =AVERAGEIFS(Clean_Data!$I:$I, Clean_Data!$D:$D, "TN12") -> 24.25
A15: KL02 | B15: =AVERAGEIFS(Clean_Data!$I:$I, Clean_Data!$D:$D, "KL02") -> 21.862069
A18: Order Count by Day of Week | E18: Orders by Delivery_Status
A19: Monday | B19: =COUNTIFS(Clean_Data!$O:$O, "Monday") -> 23 | E19: Fast | F19: =COUNTIF(Clean_Data!$Q:$Q, "Fast") -> 72
A20: Tuesday | B20: =COUNTIFS(Clean_Data!$O:$O, "Tuesday") -> 24 | E20: Normal | F20: =COUNTIF(Clean_Data!$Q:$Q, "Normal") -> 65
A21: Wednesday | B21: =COUNTIFS(Clean_Data!$O:$O, "Wednesday") -> 23 | E21: Slow | F21: =COUNTIF(Clean_Data!$Q:$Q, "Slow") -> 23
A22: Thursday | B22: =COUNTIFS(Clean_Data!$O:$O, "Thursday") -> 24
A23: Friday | B23: =COUNTIFS(Clean_Data!$O:$O, "Friday") -> 22
A24: Saturday | B24: =COUNTIFS(Clean_Data!$O:$O, "Saturday") -> 22
A25: Sunday | B25: =COUNTIFS(Clean_Data!$O:$O, "Sunday") -> 22
B26: =SUM(B19:B25) -> 160
A39: Current Total Revenue | B39: =SUM(Clean_Data!$H:$H) -> 31505
A41: % Increase in Order Value | B41: 0
A43: Projected Revenue | B43: =B39*(1+B41) -> 31505
B45: =B43 -> 31505
A46: 0 | B46: 31505
A47: 0.05 | B47: 33080.25
A48: 0.1 | B48: 34655.5
A49: 0.15 | B49: 36230.75
A50: 0.2 | B50: 37806
A51: 0.25 | B51: 39381.25

Sheet Pivot Tables
A1: Pivot_Revenue_BranchMonth | B1: Column Labels | J1: Row Labels | K1: Pivot_AvgRating_Branch
A2: Row Labels | B2: AP02 | C2: BLR01 | D2: HYD10 | E2: KL02 | F2: TN12 | G2: Grand Total | J2: AP02 | K2: 2.952381
A3: 46023 | B3: 0 | C3: 80 | D3: 0 | E3: 127 | F3: 0 | G3: 207 | J3: BLR01 | K3: 3.2641509
A4: 46054 | B4: 867 | C4: 1959 | D4: 1070 | E4: 750 | F4: 1191 | G4: 5837 | J4: HYD10 | K4: 2.9090909
A5: 46082 | B5: 864 | C5: 2382 | D5: 880 | E5: 1064 | F5: 1155 | G5: 6345 | J5: KL02 | K5: 3.3448276
A6: 46113 | B6: 797 | C6: 2014 | D6: 1134 | E6: 989 | F6: 879 | G6: 5813 | J6: TN12 | K6: 3.1666667
A7: 46143 | B7: 660 | C7: 1960 | D7: 1354 | E7: 1148 | F7: 884 | G7: 6006 | J7: Grand Total | K7: 3.15
A8: 46174 | B8: 718 | C8: 1645 | D8: 1635 | E8: 989 | F8: 880 | G8: 5867
A9: 46204 | B9: 237 | C9: 465 | D9: 130 | E9: 386 | F9: 212 | G9: 1430
A10: Grand Total | B10: 4143 | C10: 10505 | D10: 6203 | E10: 5453 | F10: 5201 | G10: 31505
I18: Pivot_Orders_DayDeliveryStatus | J18: Column Labels
A19: Row Labels | B19: Pivot_Orders By Cuisine | I19: Row Labels | J19: Fast | K19: Normal | L19: Slow | M19: Grand Total
A20: Chinese | B20: 24 | I20: Monday | J20: 10 | K20: 9 | L20: 4 | M20: 23
A21: Deserts/Bakery | B21: 27 | I21: Tuesday | J21: 10 | K21: 12 | L21: 2 | M21: 24
A22: Fast Food | B22: 37 | I22: Wednesday | J22: 11 | K22: 10 | L22: 2 | M22: 23
A23: North Indian | B23: 37 | I23: Thursday | J23: 11 | K23: 8 | L23: 5 | M23: 24
A24: South Indian | B24: 35 | I24: Friday | J24: 11 | K24: 10 | L24: 1 | M24: 22
A25: Grand Total | B25: 160 | I25: Saturday | J25: 8 | K25: 9 | L25: 5 | M25: 22
I26: Sunday | J26: 11 | K26: 7 | L26: 4 | M26: 22
I27: Grand Total | J27: 72 | K27: 65 | L27: 23 | M27: 160

Sheet Dashboard
N1: Order Share by Cuisine
A2: Monthly Revenue Trend by Branch
N24: Delivery Performance by Day
A25: Average Customer Rating by Branch
